Loading config from /home/runner/work/icloud-drive-docker/icloud-drive-docker/tests/data/test_config.yaml ...
[38;21m2023-10-12 05:31:58,154 :: DEBUG :: icloudpy.base :: base.py :: 246 :: Using session file /tmp/icloudpy/runner/quentintarantinohotmailfr.session[0m
[38;5;39m2023-10-12 05:31:58,154 :: INFO :: icloudpy.base :: base.py :: 253 :: Session file does not exist[0m
[38;21m2023-10-12 05:31:58,155 :: DEBUG :: icloudpy.base :: base.py :: 318 :: Authenticating as quentintarantino@hotmail.fr[0m
[38;21m2023-10-12 05:31:58,155 :: DEBUG :: icloudpy.base :: base.py :: 350 :: Authentication completed successfully[0m
[38;21m2023-10-12 05:31:58,158 :: DEBUG :: root :: config_parser.py :: 111 :: Checking root destination ...[0m
[38;21m2023-10-12 05:31:58,159 :: DEBUG :: icloudpy.base :: base.py :: 246 :: Using session file session_data/quentintarantinohotmailfr.session[0m
[38;5;39m2023-10-12 05:31:58,159 :: INFO :: icloudpy.base :: base.py :: 253 :: Session file does not exist[0m
[38;21m2023-10-12 05:31:58,160 :: DEBUG :: icloudpy.base :: base.py :: 318 :: Authenticating as quentintarantino@hotmail.fr[0m
[38;21m2023-10-12 05:31:58,160 :: DEBUG :: icloudpy.base :: base.py :: 350 :: Authentication completed successfully[0m
[38;5;226m2023-10-12 05:31:58,160 :: WARNING :: root :: sync.py :: 87 :: Nothing to sync. Please add drive: and/or photos: section in config.yaml file.[0m
[38;5;39m2023-10-12 05:31:58,160 :: INFO :: root :: sync.py :: 139 :: Resyncing at Thu Oct 12 05:31:58 2023 ...[0m
