[38;21m2025-10-18 19:47:02,254 :: DEBUG :: icloudpy.base :: base.py :: 240 :: Using session file /tmp/icloudpy/runner/quentintarantinohotmailfr.session[0m
[38;5;39m2025-10-18 19:47:02,254 :: INFO :: icloudpy.base :: base.py :: 247 :: Session file does not exist[0m
[38;21m2025-10-18 19:47:02,255 :: DEBUG :: icloudpy.base :: base.py :: 313 :: Authenticating as quentintarantino@hotmail.fr[0m
[38;21m2025-10-18 19:47:02,263 :: DEBUG :: icloudpy.base :: base.py :: 417 :: Authentication completed successfully[0m
[38;21m2025-10-18 19:47:02,266 :: DEBUG :: root :: usage.py :: 394 :: Usage tracking alive check started[0m
[38;21m2025-10-18 19:47:02,266 :: DEBUG :: root :: config_logging.py :: 44 :: Checking root destination ...[0m
[38;21m2025-10-18 19:47:02,267 :: DEBUG :: root :: usage.py :: 40 :: Initialized usage cache at: /config/.data[0m
[38;21m2025-10-18 19:47:02,267 :: DEBUG :: root :: usage.py :: 93 :: Loaded and validated usage cache from: /config/.data[0m
[38;21m2025-10-18 19:47:02,267 :: DEBUG :: root :: usage.py :: 410 :: Installation already registered, checking heartbeat[0m
[38;21m2025-10-18 19:47:02,267 :: DEBUG :: root :: usage.py :: 350 :: Time since last heartbeat: 0:00:00.115060[0m
[38;21m2025-10-18 19:47:02,267 :: DEBUG :: root :: usage.py :: 362 :: Heartbeat throttled (same UTC day)[0m
[38;21m2025-10-18 19:47:02,267 :: DEBUG :: root :: usage.py :: 417 :: No heartbeat required or heartbeat failed[0m
[38;5;39m2025-10-18 19:47:02,267 :: INFO :: root :: config_logging.py :: 35 :: Syncing drive every 1 seconds.[0m
[38;5;39m2025-10-18 19:47:02,268 :: INFO :: root :: config_logging.py :: 35 :: Syncing photos every 2 seconds.[0m
[38;21m2025-10-18 19:47:02,268 :: DEBUG :: icloudpy.base :: base.py :: 240 :: Using session file /config/session_data/quentintarantinohotmailfr.session[0m
[38;5;39m2025-10-18 19:47:02,268 :: INFO :: icloudpy.base :: base.py :: 247 :: Session file does not exist[0m
[38;21m2025-10-18 19:47:02,268 :: DEBUG :: icloudpy.base :: base.py :: 313 :: Authenticating as quentintarantino@hotmail.fr[0m
[38;21m2025-10-18 19:47:02,277 :: DEBUG :: icloudpy.base :: base.py :: 417 :: Authentication completed successfully[0m
[38;21m2025-10-18 19:47:02,277 :: DEBUG :: root :: config_logging.py :: 44 :: Checking drive destination ...[0m
[38;21m2025-10-18 19:47:02,277 :: DEBUG :: root :: config_logging.py :: 44 :: Checking root destination ...[0m
[38;5;39m2025-10-18 19:47:02,277 :: INFO :: root :: sync.py :: 190 :: Syncing drive...[0m
[38;5;39m2025-10-18 19:47:02,278 :: INFO :: root :: sync.py :: 192 :: Drive synced[0m
[38;21m2025-10-18 19:47:02,278 :: DEBUG :: root :: config_logging.py :: 44 :: Checking photos destination ...[0m
[38;21m2025-10-18 19:47:02,278 :: DEBUG :: root :: config_logging.py :: 44 :: Checking root destination ...[0m
[38;5;39m2025-10-18 19:47:02,278 :: INFO :: root :: sync.py :: 257 :: Syncing photos...[0m
[38;5;39m2025-10-18 19:47:02,278 :: INFO :: root :: sync.py :: 259 :: Photos synced[0m
[38;21m2025-10-18 19:47:02,279 :: DEBUG :: root :: usage.py :: 394 :: Usage tracking alive check started[0m
[38;21m2025-10-18 19:47:02,279 :: DEBUG :: root :: config_logging.py :: 44 :: Checking root destination ...[0m
[38;21m2025-10-18 19:47:02,279 :: DEBUG :: root :: usage.py :: 40 :: Initialized usage cache at: /config/.data[0m
[38;21m2025-10-18 19:47:02,279 :: DEBUG :: root :: usage.py :: 93 :: Loaded and validated usage cache from: /config/.data[0m
[38;21m2025-10-18 19:47:02,279 :: DEBUG :: root :: usage.py :: 410 :: Installation already registered, checking heartbeat[0m
[38;21m2025-10-18 19:47:02,279 :: DEBUG :: root :: usage.py :: 350 :: Time since last heartbeat: 0:00:00.127213[0m
[38;21m2025-10-18 19:47:02,279 :: DEBUG :: root :: usage.py :: 362 :: Heartbeat throttled (same UTC day)[0m
[38;21m2025-10-18 19:47:02,279 :: DEBUG :: root :: usage.py :: 417 :: No heartbeat required or heartbeat failed[0m
[38;21m2025-10-18 19:47:02,280 :: DEBUG :: root :: notify.py :: 595 :: Sync summary notification skipped (not enabled or no activity)[0m
[38;5;39m2025-10-18 19:47:02,280 :: INFO :: root :: sync.py :: 495 :: Resyncing at Sat Oct 18 19:47:03 2025 ...[0m
[38;21m2025-10-18 19:47:02,280 :: DEBUG :: root :: usage.py :: 394 :: Usage tracking alive check started[0m
[38;21m2025-10-18 19:47:02,280 :: DEBUG :: root :: config_logging.py :: 44 :: Checking root destination ...[0m
[38;21m2025-10-18 19:47:02,280 :: DEBUG :: root :: usage.py :: 40 :: Initialized usage cache at: /config/.data[0m
[38;21m2025-10-18 19:47:02,280 :: DEBUG :: root :: usage.py :: 93 :: Loaded and validated usage cache from: /config/.data[0m
[38;21m2025-10-18 19:47:02,280 :: DEBUG :: root :: usage.py :: 410 :: Installation already registered, checking heartbeat[0m
[38;21m2025-10-18 19:47:02,281 :: DEBUG :: root :: usage.py :: 350 :: Time since last heartbeat: 0:00:00.128545[0m
[38;21m2025-10-18 19:47:02,281 :: DEBUG :: root :: usage.py :: 362 :: Heartbeat throttled (same UTC day)[0m
[38;21m2025-10-18 19:47:02,281 :: DEBUG :: root :: usage.py :: 417 :: No heartbeat required or heartbeat failed[0m
[38;21m2025-10-18 19:47:02,281 :: DEBUG :: icloudpy.base :: base.py :: 240 :: Using session file /config/session_data/quentintarantinohotmailfr.session[0m
[38;5;39m2025-10-18 19:47:02,281 :: INFO :: icloudpy.base :: base.py :: 247 :: Session file does not exist[0m
[38;21m2025-10-18 19:47:02,281 :: DEBUG :: icloudpy.base :: base.py :: 313 :: Authenticating as quentintarantino@hotmail.fr[0m
[38;21m2025-10-18 19:47:02,290 :: DEBUG :: icloudpy.base :: base.py :: 417 :: Authentication completed successfully[0m
[38;21m2025-10-18 19:47:02,290 :: DEBUG :: root :: config_logging.py :: 44 :: Checking drive destination ...[0m
[38;21m2025-10-18 19:47:02,290 :: DEBUG :: root :: config_logging.py :: 44 :: Checking root destination ...[0m
[38;5;39m2025-10-18 19:47:02,290 :: INFO :: root :: sync.py :: 190 :: Syncing drive...[0m
[38;5;39m2025-10-18 19:47:02,291 :: INFO :: root :: sync.py :: 192 :: Drive synced[0m
[38;21m2025-10-18 19:47:02,291 :: DEBUG :: root :: usage.py :: 394 :: Usage tracking alive check started[0m
[38;21m2025-10-18 19:47:02,291 :: DEBUG :: root :: config_logging.py :: 44 :: Checking root destination ...[0m
[38;21m2025-10-18 19:47:02,291 :: DEBUG :: root :: usage.py :: 40 :: Initialized usage cache at: /config/.data[0m
[38;21m2025-10-18 19:47:02,291 :: DEBUG :: root :: usage.py :: 93 :: Loaded and validated usage cache from: /config/.data[0m
[38;21m2025-10-18 19:47:02,291 :: DEBUG :: root :: usage.py :: 410 :: Installation already registered, checking heartbeat[0m
[38;21m2025-10-18 19:47:02,291 :: DEBUG :: root :: usage.py :: 350 :: Time since last heartbeat: 0:00:00.139452[0m
[38;21m2025-10-18 19:47:02,292 :: DEBUG :: root :: usage.py :: 362 :: Heartbeat throttled (same UTC day)[0m
[38;21m2025-10-18 19:47:02,292 :: DEBUG :: root :: usage.py :: 417 :: No heartbeat required or heartbeat failed[0m
[38;5;39m2025-10-18 19:47:02,292 :: INFO :: root :: sync.py :: 495 :: Resyncing at Sat Oct 18 19:47:02 2025 ...[0m
[38;21m2025-10-18 19:47:02,292 :: DEBUG :: root :: usage.py :: 394 :: Usage tracking alive check started[0m
[38;21m2025-10-18 19:47:02,292 :: DEBUG :: root :: config_logging.py :: 44 :: Checking root destination ...[0m
[38;21m2025-10-18 19:47:02,292 :: DEBUG :: root :: usage.py :: 40 :: Initialized usage cache at: /config/.data[0m
[38;21m2025-10-18 19:47:02,292 :: DEBUG :: root :: usage.py :: 93 :: Loaded and validated usage cache from: /config/.data[0m
[38;21m2025-10-18 19:47:02,292 :: DEBUG :: root :: usage.py :: 410 :: Installation already registered, checking heartbeat[0m
[38;21m2025-10-18 19:47:02,293 :: DEBUG :: root :: usage.py :: 350 :: Time since last heartbeat: 0:00:00.140639[0m
[38;21m2025-10-18 19:47:02,293 :: DEBUG :: root :: usage.py :: 362 :: Heartbeat throttled (same UTC day)[0m
[38;21m2025-10-18 19:47:02,293 :: DEBUG :: root :: usage.py :: 417 :: No heartbeat required or heartbeat failed[0m
[38;21m2025-10-18 19:47:02,293 :: DEBUG :: icloudpy.base :: base.py :: 240 :: Using session file /config/session_data/quentintarantinohotmailfr.session[0m
[38;5;39m2025-10-18 19:47:02,293 :: INFO :: icloudpy.base :: base.py :: 247 :: Session file does not exist[0m
[38;21m2025-10-18 19:47:02,294 :: DEBUG :: icloudpy.base :: base.py :: 313 :: Authenticating as quentintarantino@hotmail.fr[0m
[38;21m2025-10-18 19:47:02,302 :: DEBUG :: icloudpy.base :: base.py :: 417 :: Authentication completed successfully[0m
[38;21m2025-10-18 19:47:02,302 :: DEBUG :: root :: config_logging.py :: 44 :: Checking drive destination ...[0m
[38;21m2025-10-18 19:47:02,302 :: DEBUG :: root :: config_logging.py :: 44 :: Checking root destination ...[0m
[38;5;39m2025-10-18 19:47:02,303 :: INFO :: root :: sync.py :: 190 :: Syncing drive...[0m
[38;5;39m2025-10-18 19:47:02,303 :: INFO :: root :: sync.py :: 192 :: Drive synced[0m
[38;21m2025-10-18 19:47:02,303 :: DEBUG :: root :: usage.py :: 394 :: Usage tracking alive check started[0m
[38;21m2025-10-18 19:47:02,303 :: DEBUG :: root :: config_logging.py :: 44 :: Checking root destination ...[0m
[38;21m2025-10-18 19:47:02,303 :: DEBUG :: root :: usage.py :: 40 :: Initialized usage cache at: /config/.data[0m
[38;21m2025-10-18 19:47:02,303 :: DEBUG :: root :: usage.py :: 93 :: Loaded and validated usage cache from: /config/.data[0m
[38;21m2025-10-18 19:47:02,303 :: DEBUG :: root :: usage.py :: 410 :: Installation already registered, checking heartbeat[0m
[38;21m2025-10-18 19:47:02,304 :: DEBUG :: root :: usage.py :: 350 :: Time since last heartbeat: 0:00:00.151523[0m
[38;21m2025-10-18 19:47:02,304 :: DEBUG :: root :: usage.py :: 362 :: Heartbeat throttled (same UTC day)[0m
[38;21m2025-10-18 19:47:02,304 :: DEBUG :: root :: usage.py :: 417 :: No heartbeat required or heartbeat failed[0m
[38;5;39m2025-10-18 19:47:02,304 :: INFO :: root :: sync.py :: 495 :: Resyncing at Sat Oct 18 19:47:03 2025 ...[0m
[38;21m2025-10-18 19:47:02,304 :: DEBUG :: root :: usage.py :: 394 :: Usage tracking alive check started[0m
[38;21m2025-10-18 19:47:02,304 :: DEBUG :: root :: config_logging.py :: 44 :: Checking root destination ...[0m
[38;21m2025-10-18 19:47:02,304 :: DEBUG :: root :: usage.py :: 40 :: Initialized usage cache at: /config/.data[0m
[38;21m2025-10-18 19:47:02,304 :: DEBUG :: root :: usage.py :: 93 :: Loaded and validated usage cache from: /config/.data[0m
[38;21m2025-10-18 19:47:02,305 :: DEBUG :: root :: usage.py :: 410 :: Installation already registered, checking heartbeat[0m
[38;21m2025-10-18 19:47:02,305 :: DEBUG :: root :: usage.py :: 350 :: Time since last heartbeat: 0:00:00.152717[0m
[38;21m2025-10-18 19:47:02,305 :: DEBUG :: root :: usage.py :: 362 :: Heartbeat throttled (same UTC day)[0m
[38;21m2025-10-18 19:47:02,305 :: DEBUG :: root :: usage.py :: 417 :: No heartbeat required or heartbeat failed[0m
[38;21m2025-10-18 19:47:02,305 :: DEBUG :: icloudpy.base :: base.py :: 240 :: Using session file /config/session_data/quentintarantinohotmailfr.session[0m
[38;5;39m2025-10-18 19:47:02,305 :: INFO :: icloudpy.base :: base.py :: 247 :: Session file does not exist[0m
[38;21m2025-10-18 19:47:02,306 :: DEBUG :: icloudpy.base :: base.py :: 313 :: Authenticating as quentintarantino@hotmail.fr[0m
[38;21m2025-10-18 19:47:02,314 :: DEBUG :: icloudpy.base :: base.py :: 417 :: Authentication completed successfully[0m
[38;21m2025-10-18 19:47:02,314 :: DEBUG :: root :: config_logging.py :: 44 :: Checking photos destination ...[0m
[38;21m2025-10-18 19:47:02,314 :: DEBUG :: root :: config_logging.py :: 44 :: Checking root destination ...[0m
[38;5;39m2025-10-18 19:47:02,315 :: INFO :: root :: sync.py :: 257 :: Syncing photos...[0m
[38;5;39m2025-10-18 19:47:02,315 :: INFO :: root :: sync.py :: 259 :: Photos synced[0m
[38;21m2025-10-18 19:47:02,315 :: DEBUG :: root :: usage.py :: 394 :: Usage tracking alive check started[0m
[38;21m2025-10-18 19:47:02,315 :: DEBUG :: root :: config_logging.py :: 44 :: Checking root destination ...[0m
[38;21m2025-10-18 19:47:02,315 :: DEBUG :: root :: usage.py :: 40 :: Initialized usage cache at: /config/.data[0m
[38;21m2025-10-18 19:47:02,316 :: DEBUG :: root :: usage.py :: 93 :: Loaded and validated usage cache from: /config/.data[0m
[38;21m2025-10-18 19:47:02,316 :: DEBUG :: root :: usage.py :: 410 :: Installation already registered, checking heartbeat[0m
[38;21m2025-10-18 19:47:02,316 :: DEBUG :: root :: usage.py :: 350 :: Time since last heartbeat: 0:00:00.163921[0m
[38;21m2025-10-18 19:47:02,316 :: DEBUG :: root :: usage.py :: 362 :: Heartbeat throttled (same UTC day)[0m
[38;21m2025-10-18 19:47:02,316 :: DEBUG :: root :: usage.py :: 417 :: No heartbeat required or heartbeat failed[0m
[38;5;39m2025-10-18 19:47:02,316 :: INFO :: root :: sync.py :: 495 :: Resyncing at Sat Oct 18 19:47:03 2025 ...[0m
[38;21m2025-10-18 19:47:02,316 :: DEBUG :: root :: usage.py :: 394 :: Usage tracking alive check started[0m
[38;21m2025-10-18 19:47:02,317 :: DEBUG :: root :: config_logging.py :: 44 :: Checking root destination ...[0m
[38;21m2025-10-18 19:47:02,317 :: DEBUG :: root :: usage.py :: 40 :: Initialized usage cache at: /config/.data[0m
[38;21m2025-10-18 19:47:02,317 :: DEBUG :: root :: usage.py :: 93 :: Loaded and validated usage cache from: /config/.data[0m
[38;21m2025-10-18 19:47:02,317 :: DEBUG :: root :: usage.py :: 410 :: Installation already registered, checking heartbeat[0m
[38;21m2025-10-18 19:47:02,317 :: DEBUG :: root :: usage.py :: 350 :: Time since last heartbeat: 0:00:00.165116[0m
[38;21m2025-10-18 19:47:02,317 :: DEBUG :: root :: usage.py :: 362 :: Heartbeat throttled (same UTC day)[0m
[38;21m2025-10-18 19:47:02,317 :: DEBUG :: root :: usage.py :: 417 :: No heartbeat required or heartbeat failed[0m
[38;21m2025-10-18 19:47:02,318 :: DEBUG :: icloudpy.base :: base.py :: 240 :: Using session file /config/session_data/quentintarantinohotmailfr.session[0m
[38;5;39m2025-10-18 19:47:02,318 :: INFO :: icloudpy.base :: base.py :: 247 :: Session file does not exist[0m
[38;21m2025-10-18 19:47:02,318 :: DEBUG :: icloudpy.base :: base.py :: 313 :: Authenticating as quentintarantino@hotmail.fr[0m
[38;21m2025-10-18 19:47:02,327 :: DEBUG :: icloudpy.base :: base.py :: 417 :: Authentication completed successfully[0m
[38;21m2025-10-18 19:47:02,327 :: DEBUG :: root :: config_logging.py :: 44 :: Checking drive destination ...[0m
[38;21m2025-10-18 19:47:02,327 :: DEBUG :: root :: config_logging.py :: 44 :: Checking root destination ...[0m
[38;5;39m2025-10-18 19:47:02,327 :: INFO :: root :: sync.py :: 190 :: Syncing drive...[0m
[38;5;39m2025-10-18 19:47:02,327 :: INFO :: root :: sync.py :: 192 :: Drive synced[0m
[38;21m2025-10-18 19:47:02,327 :: DEBUG :: root :: usage.py :: 394 :: Usage tracking alive check started[0m
[38;21m2025-10-18 19:47:02,327 :: DEBUG :: root :: config_logging.py :: 44 :: Checking root destination ...[0m
[38;21m2025-10-18 19:47:02,328 :: DEBUG :: root :: usage.py :: 40 :: Initialized usage cache at: /config/.data[0m
[38;21m2025-10-18 19:47:02,328 :: DEBUG :: root :: usage.py :: 93 :: Loaded and validated usage cache from: /config/.data[0m
[38;21m2025-10-18 19:47:02,328 :: DEBUG :: root :: usage.py :: 410 :: Installation already registered, checking heartbeat[0m
[38;21m2025-10-18 19:47:02,328 :: DEBUG :: root :: usage.py :: 350 :: Time since last heartbeat: 0:00:00.176075[0m
[38;21m2025-10-18 19:47:02,328 :: DEBUG :: root :: usage.py :: 362 :: Heartbeat throttled (same UTC day)[0m
[38;21m2025-10-18 19:47:02,328 :: DEBUG :: root :: usage.py :: 417 :: No heartbeat required or heartbeat failed[0m
[38;5;39m2025-10-18 19:47:02,328 :: INFO :: root :: sync.py :: 495 :: Resyncing at Sat Oct 18 19:47:02 2025 ...[0m
[38;21m2025-10-18 19:47:02,329 :: DEBUG :: root :: usage.py :: 394 :: Usage tracking alive check started[0m
[38;21m2025-10-18 19:47:02,329 :: DEBUG :: root :: config_logging.py :: 44 :: Checking root destination ...[0m
[38;21m2025-10-18 19:47:02,329 :: DEBUG :: root :: usage.py :: 40 :: Initialized usage cache at: /config/.data[0m
[38;21m2025-10-18 19:47:02,329 :: DEBUG :: root :: usage.py :: 93 :: Loaded and validated usage cache from: /config/.data[0m
[38;21m2025-10-18 19:47:02,329 :: DEBUG :: root :: usage.py :: 410 :: Installation already registered, checking heartbeat[0m
[38;21m2025-10-18 19:47:02,329 :: DEBUG :: root :: usage.py :: 350 :: Time since last heartbeat: 0:00:00.177295[0m
[38;21m2025-10-18 19:47:02,329 :: DEBUG :: root :: usage.py :: 362 :: Heartbeat throttled (same UTC day)[0m
[38;21m2025-10-18 19:47:02,329 :: DEBUG :: root :: usage.py :: 417 :: No heartbeat required or heartbeat failed[0m
[38;21m2025-10-18 19:47:02,330 :: DEBUG :: icloudpy.base :: base.py :: 240 :: Using session file /config/session_data/quentintarantinohotmailfr.session[0m
[38;5;39m2025-10-18 19:47:02,330 :: INFO :: icloudpy.base :: base.py :: 247 :: Session file does not exist[0m
[38;21m2025-10-18 19:47:02,330 :: DEBUG :: icloudpy.base :: base.py :: 313 :: Authenticating as quentintarantino@hotmail.fr[0m
[38;21m2025-10-18 19:47:02,339 :: DEBUG :: icloudpy.base :: base.py :: 417 :: Authentication completed successfully[0m
[38;21m2025-10-18 19:47:02,339 :: DEBUG :: root :: config_logging.py :: 44 :: Checking drive destination ...[0m
[38;21m2025-10-18 19:47:02,339 :: DEBUG :: root :: config_logging.py :: 44 :: Checking root destination ...[0m
[38;5;39m2025-10-18 19:47:02,339 :: INFO :: root :: sync.py :: 190 :: Syncing drive...[0m
[38;5;39m2025-10-18 19:47:02,339 :: INFO :: root :: sync.py :: 192 :: Drive synced[0m
[38;21m2025-10-18 19:47:02,339 :: DEBUG :: root :: usage.py :: 394 :: Usage tracking alive check started[0m
[38;21m2025-10-18 19:47:02,340 :: DEBUG :: root :: config_logging.py :: 44 :: Checking root destination ...[0m
[38;21m2025-10-18 19:47:02,340 :: DEBUG :: root :: usage.py :: 40 :: Initialized usage cache at: /config/.data[0m
[38;21m2025-10-18 19:47:02,340 :: DEBUG :: root :: usage.py :: 93 :: Loaded and validated usage cache from: /config/.data[0m
[38;21m2025-10-18 19:47:02,340 :: DEBUG :: root :: usage.py :: 410 :: Installation already registered, checking heartbeat[0m
[38;21m2025-10-18 19:47:02,340 :: DEBUG :: root :: usage.py :: 350 :: Time since last heartbeat: 0:00:00.188151[0m
[38;21m2025-10-18 19:47:02,340 :: DEBUG :: root :: usage.py :: 362 :: Heartbeat throttled (same UTC day)[0m
[38;21m2025-10-18 19:47:02,340 :: DEBUG :: root :: usage.py :: 417 :: No heartbeat required or heartbeat failed[0m
[38;5;39m2025-10-18 19:47:02,340 :: INFO :: root :: sync.py :: 495 :: Resyncing at Sat Oct 18 19:47:03 2025 ...[0m
[38;21m2025-10-18 19:47:02,341 :: DEBUG :: root :: usage.py :: 394 :: Usage tracking alive check started[0m
[38;21m2025-10-18 19:47:02,341 :: DEBUG :: root :: config_logging.py :: 44 :: Checking root destination ...[0m
[38;21m2025-10-18 19:47:02,341 :: DEBUG :: root :: usage.py :: 40 :: Initialized usage cache at: /config/.data[0m
[38;21m2025-10-18 19:47:02,341 :: DEBUG :: root :: usage.py :: 93 :: Loaded and validated usage cache from: /config/.data[0m
[38;21m2025-10-18 19:47:02,341 :: DEBUG :: root :: usage.py :: 410 :: Installation already registered, checking heartbeat[0m
[38;21m2025-10-18 19:47:02,341 :: DEBUG :: root :: usage.py :: 350 :: Time since last heartbeat: 0:00:00.189389[0m
[38;21m2025-10-18 19:47:02,341 :: DEBUG :: root :: usage.py :: 362 :: Heartbeat throttled (same UTC day)[0m
[38;21m2025-10-18 19:47:02,342 :: DEBUG :: root :: usage.py :: 417 :: No heartbeat required or heartbeat failed[0m
[38;21m2025-10-18 19:47:02,342 :: DEBUG :: icloudpy.base :: base.py :: 240 :: Using session file /config/session_data/quentintarantinohotmailfr.session[0m
[38;5;39m2025-10-18 19:47:02,342 :: INFO :: icloudpy.base :: base.py :: 247 :: Session file does not exist[0m
[38;21m2025-10-18 19:47:02,342 :: DEBUG :: icloudpy.base :: base.py :: 313 :: Authenticating as quentintarantino@hotmail.fr[0m
[38;21m2025-10-18 19:47:02,351 :: DEBUG :: icloudpy.base :: base.py :: 417 :: Authentication completed successfully[0m
[38;21m2025-10-18 19:47:02,351 :: DEBUG :: root :: config_logging.py :: 44 :: Checking photos destination ...[0m
[38;21m2025-10-18 19:47:02,351 :: DEBUG :: root :: config_logging.py :: 44 :: Checking root destination ...[0m
[38;5;39m2025-10-18 19:47:02,351 :: INFO :: root :: sync.py :: 257 :: Syncing photos...[0m
[38;5;39m2025-10-18 19:47:02,352 :: INFO :: root :: sync.py :: 259 :: Photos synced[0m
[38;21m2025-10-18 19:47:02,352 :: DEBUG :: root :: usage.py :: 394 :: Usage tracking alive check started[0m
[38;21m2025-10-18 19:47:02,352 :: DEBUG :: root :: config_logging.py :: 44 :: Checking root destination ...[0m
[38;21m2025-10-18 19:47:02,352 :: DEBUG :: root :: usage.py :: 40 :: Initialized usage cache at: /config/.data[0m
[38;21m2025-10-18 19:47:02,352 :: DEBUG :: root :: usage.py :: 93 :: Loaded and validated usage cache from: /config/.data[0m
[38;21m2025-10-18 19:47:02,352 :: DEBUG :: root :: usage.py :: 410 :: Installation already registered, checking heartbeat[0m
[38;21m2025-10-18 19:47:02,353 :: DEBUG :: root :: usage.py :: 350 :: Time since last heartbeat: 0:00:00.200570[0m
[38;21m2025-10-18 19:47:02,353 :: DEBUG :: root :: usage.py :: 362 :: Heartbeat throttled (same UTC day)[0m
[38;21m2025-10-18 19:47:02,353 :: DEBUG :: root :: usage.py :: 417 :: No heartbeat required or heartbeat failed[0m
[38;5;39m2025-10-18 19:47:02,353 :: INFO :: root :: sync.py :: 495 :: Resyncing at Sat Oct 18 19:47:03 2025 ...[0m
[38;21m2025-10-18 19:47:02,353 :: DEBUG :: root :: usage.py :: 394 :: Usage tracking alive check started[0m
[38;21m2025-10-18 19:47:02,353 :: DEBUG :: root :: config_logging.py :: 44 :: Checking root destination ...[0m
[38;21m2025-10-18 19:47:02,353 :: DEBUG :: root :: usage.py :: 40 :: Initialized usage cache at: /config/.data[0m
[38;21m2025-10-18 19:47:02,354 :: DEBUG :: root :: usage.py :: 93 :: Loaded and validated usage cache from: /config/.data[0m
[38;21m2025-10-18 19:47:02,354 :: DEBUG :: root :: usage.py :: 410 :: Installation already registered, checking heartbeat[0m
[38;21m2025-10-18 19:47:02,354 :: DEBUG :: root :: usage.py :: 350 :: Time since last heartbeat: 0:00:00.201778[0m
[38;21m2025-10-18 19:47:02,354 :: DEBUG :: root :: usage.py :: 362 :: Heartbeat throttled (same UTC day)[0m
[38;21m2025-10-18 19:47:02,354 :: DEBUG :: root :: usage.py :: 417 :: No heartbeat required or heartbeat failed[0m
[38;21m2025-10-18 19:47:02,354 :: DEBUG :: icloudpy.base :: base.py :: 240 :: Using session file /config/session_data/quentintarantinohotmailfr.session[0m
[38;5;39m2025-10-18 19:47:02,354 :: INFO :: icloudpy.base :: base.py :: 247 :: Session file does not exist[0m
[38;21m2025-10-18 19:47:02,355 :: DEBUG :: icloudpy.base :: base.py :: 313 :: Authenticating as quentintarantino@hotmail.fr[0m
[38;21m2025-10-18 19:47:02,363 :: DEBUG :: icloudpy.base :: base.py :: 417 :: Authentication completed successfully[0m
[38;21m2025-10-18 19:47:02,363 :: DEBUG :: root :: config_logging.py :: 44 :: Checking drive destination ...[0m
[38;21m2025-10-18 19:47:02,364 :: DEBUG :: root :: config_logging.py :: 44 :: Checking root destination ...[0m
[38;5;39m2025-10-18 19:47:02,364 :: INFO :: root :: sync.py :: 190 :: Syncing drive...[0m
[38;5;39m2025-10-18 19:47:02,364 :: INFO :: root :: sync.py :: 192 :: Drive synced[0m
[38;21m2025-10-18 19:47:02,364 :: DEBUG :: root :: usage.py :: 394 :: Usage tracking alive check started[0m
[38;21m2025-10-18 19:47:02,364 :: DEBUG :: root :: config_logging.py :: 44 :: Checking root destination ...[0m
[38;21m2025-10-18 19:47:02,364 :: DEBUG :: root :: usage.py :: 40 :: Initialized usage cache at: /config/.data[0m
[38;21m2025-10-18 19:47:02,365 :: DEBUG :: root :: usage.py :: 93 :: Loaded and validated usage cache from: /config/.data[0m
[38;21m2025-10-18 19:47:02,365 :: DEBUG :: root :: usage.py :: 410 :: Installation already registered, checking heartbeat[0m
[38;21m2025-10-18 19:47:02,365 :: DEBUG :: root :: usage.py :: 350 :: Time since last heartbeat: 0:00:00.212815[0m
[38;21m2025-10-18 19:47:02,365 :: DEBUG :: root :: usage.py :: 362 :: Heartbeat throttled (same UTC day)[0m
[38;21m2025-10-18 19:47:02,365 :: DEBUG :: root :: usage.py :: 417 :: No heartbeat required or heartbeat failed[0m
[38;5;39m2025-10-18 19:47:02,365 :: INFO :: root :: sync.py :: 495 :: Resyncing at Sat Oct 18 19:47:02 2025 ...[0m
