Loading config from /home/runner/work/icloud-drive-docker/icloud-drive-docker/tests/data/test_config.yaml ...
[38;21m2023-12-01 18:04:28,121 :: DEBUG :: icloudpy.base :: base.py :: 246 :: Using session file /tmp/icloudpy/runner/quentintarantinohotmailfr.session[0m
[38;5;39m2023-12-01 18:04:28,122 :: INFO :: icloudpy.base :: base.py :: 253 :: Session file does not exist[0m
[38;21m2023-12-01 18:04:28,122 :: DEBUG :: icloudpy.base :: base.py :: 318 :: Authenticating as quentintarantino@hotmail.fr[0m
[38;21m2023-12-01 18:04:28,122 :: DEBUG :: icloudpy.base :: base.py :: 350 :: Authentication completed successfully[0m
[38;21m2023-12-01 18:04:28,124 :: DEBUG :: root :: config_parser.py :: 111 :: Checking root destination ...[0m
[38;21m2023-12-01 18:04:28,125 :: DEBUG :: icloudpy.base :: base.py :: 246 :: Using session file session_data/quentintarantinohotmailfr.session[0m
[38;5;39m2023-12-01 18:04:28,125 :: INFO :: icloudpy.base :: base.py :: 253 :: Session file does not exist[0m
[38;21m2023-12-01 18:04:28,125 :: DEBUG :: icloudpy.base :: base.py :: 318 :: Authenticating as quentintarantino@hotmail.fr[0m
[38;21m2023-12-01 18:04:28,126 :: DEBUG :: icloudpy.base :: base.py :: 350 :: Authentication completed successfully[0m
[38;5;226m2023-12-01 18:04:28,126 :: WARNING :: root :: sync.py :: 93 :: Nothing to sync. Please add drive: and/or photos: section in config.yaml file.[0m
[38;5;39m2023-12-01 18:04:28,126 :: INFO :: root :: sync.py :: 145 :: Resyncing at Fri Dec  1 18:04:28 2023 ...[0m
