Loading config from /home/runner/work/icloud-drive-docker/icloud-drive-docker/tests/data/test_config.yaml ...
[38;21m2024-06-21 04:25:41,666 :: DEBUG :: icloudpy.base :: base.py :: 246 :: Using session file /tmp/icloudpy/runner/quentintarantinohotmailfr.session[0m
[38;5;39m2024-06-21 04:25:41,667 :: INFO :: icloudpy.base :: base.py :: 253 :: Session file does not exist[0m
[38;21m2024-06-21 04:25:41,667 :: DEBUG :: icloudpy.base :: base.py :: 318 :: Authenticating as quentintarantino@hotmail.fr[0m
[38;21m2024-06-21 04:25:41,667 :: DEBUG :: icloudpy.base :: base.py :: 350 :: Authentication completed successfully[0m
[38;21m2024-06-21 04:25:41,669 :: DEBUG :: root :: config_parser.py :: 113 :: Checking root destination ...[0m
[38;21m2024-06-21 04:25:41,670 :: DEBUG :: icloudpy.base :: base.py :: 246 :: Using session file session_data/quentintarantinohotmailfr.session[0m
[38;5;39m2024-06-21 04:25:41,670 :: INFO :: icloudpy.base :: base.py :: 253 :: Session file does not exist[0m
[38;21m2024-06-21 04:25:41,670 :: DEBUG :: icloudpy.base :: base.py :: 318 :: Authenticating as quentintarantino@hotmail.fr[0m
[38;21m2024-06-21 04:25:41,671 :: DEBUG :: icloudpy.base :: base.py :: 350 :: Authentication completed successfully[0m
[38;5;226m2024-06-21 04:25:41,671 :: WARNING :: root :: sync.py :: 93 :: Nothing to sync. Please add drive: and/or photos: section in config.yaml file.[0m
[38;5;39m2024-06-21 04:25:41,671 :: INFO :: root :: sync.py :: 152 :: Resyncing at Fri Jun 21 04:25:41 2024 ...[0m
